<?xml version="1.0" ?>
<!-- =================================================================================== -->
<!-- |    This document was autogenerated by xacro from /home/siddharth/ws_moveit/src/agribot_dummy_1_description/urdf/agribot_dummy_1.xacro | -->
<!-- |    EDITING THIS FILE BY HAND IS NOT RECOMMENDED                                 | -->
<!-- =================================================================================== -->
<robot name="agribot_dummy_1">
    <material name="silver_default">
        <color rgba="0.700 0.700 0.700 1.000" />
    </material>
    <material name="rubber_hard">
        <color rgba="0.15294117647058825 0.15294117647058825 0.15294117647058825 1.0" />
    </material>
    <material name="opaque565656">
        <color rgba="0.2196078431372549 0.2196078431372549 0.2196078431372549 1.0" />
    </material>
    <material name="steel_satin">
        <color rgba="0.6274509803921569 0.6274509803921569 0.6274509803921569 1.0" />
    </material>
    <material name="aluminum_satin">
        <color rgba="0.9607843137254902 0.9607843137254902 0.9647058823529412 1.0" />
    </material>
    <material name="opaque126126126">
        <color rgba="0.49411764705882355 0.49411764705882355 0.49411764705882355 1.0" />
    </material>
    <transmission name="front_right_tran">
        <type>transmission_interface/SimpleTransmission</type>
        <joint name="front_right">
            <hardwareInterface>hardware_interface/EffortJointInterface</hardwareInterface>
        </joint>
        <actuator name="front_right_actr">
            <hardwareInterface>hardware_interface/EffortJointInterface</hardwareInterface>
            <mechanicalReduction>1</mechanicalReduction>
        </actuator>
    </transmission>
    <transmission name="front_left_tran">
        <type>transmission_interface/SimpleTransmission</type>
        <joint name="front_left">
            <hardwareInterface>hardware_interface/EffortJointInterface</hardwareInterface>
        </joint>
        <actuator name="front_left_actr">
            <hardwareInterface>hardware_interface/EffortJointInterface</hardwareInterface>
            <mechanicalReduction>1</mechanicalReduction>
        </actuator>
    </transmission>
    <transmission name="back_left_tran">
        <type>transmission_interface/SimpleTransmission</type>
        <joint name="back_left">
            <hardwareInterface>hardware_interface/EffortJointInterface</hardwareInterface>
        </joint>
        <actuator name="back_left_actr">
            <hardwareInterface>hardware_interface/EffortJointInterface</hardwareInterface>
            <mechanicalReduction>1</mechanicalReduction>
        </actuator>
    </transmission>
    <transmission name="back_right_tran">
        <type>transmission_interface/SimpleTransmission</type>
        <joint name="back_right">
            <hardwareInterface>hardware_interface/EffortJointInterface</hardwareInterface>
        </joint>
        <actuator name="back_right_actr">
            <hardwareInterface>hardware_interface/EffortJointInterface</hardwareInterface>
            <mechanicalReduction>1</mechanicalReduction>
        </actuator>
    </transmission>
    <transmission name="Slider 14_tran">
        <type>transmission_interface/SimpleTransmission</type>
        <joint name="Slider">
            <hardwareInterface>hardware_interface/PositionJointInterface</hardwareInterface>
        </joint>
        <actuator name="Slider 14_actr">
            <hardwareInterface>hardware_interface/PositionJointInterface</hardwareInterface>
            <mechanicalReduction>1</mechanicalReduction>
        </actuator>
    </transmission>
    <transmission name="arm_twist_tran">
        <type>transmission_interface/SimpleTransmission</type>
        <joint name="arm_twist">
            <hardwareInterface>hardware_interface/PositionJointInterface</hardwareInterface>
        </joint>
        <actuator name="arm_twist_actr">
            <hardwareInterface>hardware_interface/PositionJointInterface</hardwareInterface>
            <mechanicalReduction>1</mechanicalReduction>
        </actuator>
    </transmission>
    <transmission name="shoulder_tran">
        <type>transmission_interface/SimpleTransmission</type>
        <joint name="shoulder">
            <hardwareInterface>hardware_interface/PositionJointInterface</hardwareInterface>
        </joint>
        <actuator name="shoulder_actr">
            <hardwareInterface>hardware_interface/PositionJointInterface</hardwareInterface>
            <mechanicalReduction>1</mechanicalReduction>
        </actuator>
    </transmission>
    <transmission name="elbow_tran">
        <type>transmission_interface/SimpleTransmission</type>
        <joint name="elbow">
            <hardwareInterface>hardware_interface/PositionJointInterface</hardwareInterface>
        </joint>
        <actuator name="elbow_actr">
            <hardwareInterface>hardware_interface/PositionJointInterface</hardwareInterface>
            <mechanicalReduction>1</mechanicalReduction>
        </actuator>
    </transmission>
    <transmission name="wrist_tran">
        <type>transmission_interface/SimpleTransmission</type>
        <joint name="wrist">
            <hardwareInterface>hardware_interface/PositionJointInterface</hardwareInterface>
        </joint>
        <actuator name="wrist_actr">
            <hardwareInterface>hardware_interface/PositionJointInterface</hardwareInterface>
            <mechanicalReduction>1</mechanicalReduction>
        </actuator>
    </transmission>
    <transmission name="right_finger_tran">
        <type>transmission_interface/SimpleTransmission</type>
        <joint name="right_finger">
            <hardwareInterface>hardware_interface/PositionJointInterface</hardwareInterface>
        </joint>
        <actuator name="right_finger_actr">
            <hardwareInterface>hardware_interface/PositionJointInterface</hardwareInterface>
            <mechanicalReduction>1</mechanicalReduction>
        </actuator>
    </transmission>
    <transmission name="left_finger_tran">
        <type>transmission_interface/SimpleTransmission</type>
        <joint name="left_finger">
            <hardwareInterface>hardware_interface/PositionJointInterface</hardwareInterface>
        </joint>
        <actuator name="left_finger_actr">
            <hardwareInterface>hardware_interface/PositionJointInterface</hardwareInterface>
            <mechanicalReduction>1</mechanicalReduction>
        </actuator>
    </transmission>
    <transmission name="camera_twist_tran">
        <type>transmission_interface/SimpleTransmission</type>
        <joint name="camera_twist">
            <hardwareInterface>hardware_interface/PositionJointInterface</hardwareInterface>
        </joint>
        <actuator name="camera_twist_actr">
            <hardwareInterface>hardware_interface/PositionJointInterface</hardwareInterface>
            <mechanicalReduction>1</mechanicalReduction>
        </actuator>
    </transmission>
<gazebo>
  <plugin name="control" filename="libgazebo_ros_control.so"/>
</gazebo>
    <gazebo reference="base_link">
        <material>Gazebo/Silver</material>
        <mu1>0.2</mu1>
        <mu2>0.2</mu2>
        <selfCollide>true</selfCollide>
        <gravity>true</gravity>
    </gazebo>
    <gazebo reference="front_right_wheel">
        <material>Gazebo/Silver</material>
        <mu1>0.9</mu1>
        <mu2>0.9</mu2>
        <selfCollide>true</selfCollide>
            <minDepth>0.001</minDepth>
            <kp>1000000</kp>
            <kd>1</kd>
        <implicitSpringDamper>true</implicitSpringDamper>
    </gazebo>
    <gazebo reference="front_left_wheel">
        <material>Gazebo/Silver</material>
        <mu1>0.9</mu1>
        <mu2>0.9</mu2>
        <selfCollide>true</selfCollide>
            <minDepth>0.001</minDepth>
            <kp>1000000</kp>
            <kd>1</kd>
        <implicitSpringDamper>true</implicitSpringDamper>
    </gazebo>
    <gazebo reference="back_left_wheel">
        <material>Gazebo/Silver</material>
        <mu1>0.9</mu1>
        <mu2>0.9</mu2>
        <selfCollide>true</selfCollide>
            <minDepth>0.001</minDepth>
            <kp>1000000</kp>
            <kd>1</kd>
        <implicitSpringDamper>true</implicitSpringDamper>
    </gazebo>
    <gazebo reference="back_right_wheel">
        <material>Gazebo/Silver</material>
        <mu1>0.9</mu1>
        <mu2>0.9</mu2>
        <selfCollide>true</selfCollide>
            <minDepth>0.001</minDepth>
            <kp>1000000</kp>
            <kd>1</kd>
        <implicitSpringDamper>true</implicitSpringDamper>
    </gazebo>
    <gazebo reference="slider_link">
        <material>Gazebo/Silver</material>
        <mu1>0.2</mu1>
        <mu2>0.2</mu2>
        <selfCollide>true</selfCollide>
    </gazebo>
    <gazebo reference="arm_base">
        <material>Gazebo/Silver</material>
        <mu1>0.2</mu1>
        <mu2>0.2</mu2>
        <selfCollide>true</selfCollide>
    </gazebo>
    <gazebo reference="link_1">
        <material>Gazebo/Silver</material>
        <mu1>0.2</mu1>
        <mu2>0.2</mu2>
        <selfCollide>true</selfCollide>
    </gazebo>
    <gazebo reference="link_2">
        <material>Gazebo/Silver</material>
        <mu1>0.2</mu1>
        <mu2>0.2</mu2>
        <selfCollide>true</selfCollide>
    </gazebo>
    <gazebo reference="link_3">
        <material>Gazebo/Silver</material>
        <mu1>0.2</mu1>
        <mu2>0.2</mu2>
        <selfCollide>true</selfCollide>
    </gazebo>
    <gazebo reference="eef_base">
        <material>Gazebo/Silver</material>
        <mu1>0.2</mu1>
        <mu2>0.2</mu2>
        <selfCollide>true</selfCollide>
    </gazebo>
    <gazebo reference="right_claw">
        <material>Gazebo/Silver</material>
        <mu1>0.2</mu1>
        <mu2>0.2</mu2>
        <selfCollide>true</selfCollide>
    </gazebo>
    <gazebo reference="left_claw">
        <material>Gazebo/Silver</material>
        <mu1>0.2</mu1>
        <mu2>0.2</mu2>
        <selfCollide>true</selfCollide>
    </gazebo>
    <gazebo reference="cam_attachment">
        <material>Gazebo/Silver</material>
        <mu1>0.2</mu1>
        <mu2>0.2</mu2>
        <selfCollide>true</selfCollide>
    </gazebo>
    <gazebo reference="Kinect">
        <material>Gazebo/Silver</material>
        <mu1>0.2</mu1>
        <mu2>0.2</mu2>
        <selfCollide>true</selfCollide>
    </gazebo>

    <gazebo>
        <plugin filename="libgazebo_ros_skid_steer_drive.so" name="skid_steer_drive_controller">
            <updateRate>10</updateRate>
            <robotNamespace>/</robotNamespace>
            <leftFrontJoint>front_left</leftFrontJoint>
            <rightFrontJoint>front_right</rightFrontJoint>
            <leftRearJoint>back_left</leftRearJoint>
            <rightRearJoint>back_right</rightRearJoint>
            <wheelSeparation>0.476.6</wheelSeparation>
            <wheelDiameter>0.2032</wheelDiameter>
            <robotBaseFrame>base_link</robotBaseFrame>
            <torque>7</torque>
            <topicName>cmd_vel</topicName>
            <broadcastTF>true</broadcastTF>
        </plugin>
    </gazebo>

    <gazebo reference="Kinect">
        <sensor name="kinect_camera" type="depth">
            <update_rate>0</update_rate>
            <camera>
                <horizontal_fov>1.24</horizontal_fov>
                <image>
                    <width>1920</width>
                    <height>1080</height>
                    <format>R8G8B8</format>
                </image>
                <clip>
                    <near>0.5</near>
                    <far>4.5</far>
                </clip>
            </camera>
            <plugin filename="libgazebo_ros_openni_kinect.so" name="Kinect_controller">
                <baseline>0.2</baseline>
                <alwaysOn>true</alwaysOn>
                <updateRate>0.0</updateRate>
                <cameraName>Kinect</cameraName>
                <imageTopicName>/Kinect/color/image_raw</imageTopicName>
                <cameraInfoTopicName>/Kinect/color/camera_info</cameraInfoTopicName>
                <depthImageTopicName>/Kinect/depth/image_raw</depthImageTopicName>
                <depthImageInfoTopicName>/Kinect/depth/camera_info</depthImageInfoTopicName>
                <pointCloudTopicName>/Kinect/depth/points</pointCloudTopicName>
                <frameName>Kinect</frameName>
                <pointCloudCutoff>0.5</pointCloudCutoff>
                <pointCloudCutoffMax>4.5</pointCloudCutoffMax>
                <distortionK1>0.00000001</distortionK1>
                <distortionK2>0.00000001</distortionK2>
                <distortionK3>0.00000001</distortionK3>
                <distortionT1>0.00000001</distortionT1>
                <distortionT2>0.00000001</distortionT2>
                <CxPrime>0</CxPrime>
                <Cx>0</Cx>
                <Cy>0</Cy>
                <focalLength>0</focalLength>
                <hackBaseline>0</hackBaseline>
            </plugin>
        </sensor>
    </gazebo>
    
    <link name="base_link">
        <inertial>
            <origin rpy="0 0 0" xyz="0.2514408376198744 -0.18000014406773893 0.22560750352264175" />
            <mass value="12.394351278281407" />
            <inertia ixx="0.331936" ixy="-0.0" ixz="-0.001939" iyy="0.640231" iyz="-0.0" izz="0.801659" />
        </inertial>
        <visual>
            <origin rpy="0 0 0" xyz="0 0 0" />
            <geometry>
                <mesh filename="package://agribot_dummy_1_description/meshes/base_link.stl" scale="0.001 0.001 0.001" />
            </geometry>
            <material name="silver_default" />
        </visual>
        <collision>
            <origin rpy="0 0 0" xyz="0 0 0" />
            <geometry>
                <mesh filename="package://agribot_dummy_1_description/meshes/base_link.stl" scale="0.001 0.001 0.001" />
            </geometry>
        </collision>
    </link>
    <link name="front_right_wheel">
        <inertial>
            <origin rpy="0 0 0" xyz="-1.1102230246251565e-16 -0.008317531517497756 3.774758283725532e-15" />
            <mass value="0.04179337834879549" />
            <inertia ixx="0.00016" ixy="0.0" ixz="-0.0" iyy="0.000316" iyz="-0.0" izz="0.00016" />
        </inertial>
        <visual>
            <origin rpy="0 0 0" xyz="-0.515 0.41 -0.102206" />
            <geometry>
                <mesh filename="package://agribot_dummy_1_description/meshes/front_right_wheel_1.stl" scale="0.001 0.001 0.001" />
            </geometry>
            <material name="rubber_hard" />
        </visual>
        <collision>
            <origin rpy="0 0 0" xyz="-0.515 0.41 -0.102206" />
            <geometry>
                <mesh filename="package://agribot_dummy_1_description/meshes/front_right_wheel_1.stl" scale="0.001 0.001 0.001" />
            </geometry>
        </collision>
    </link>
    <link name="front_left_wheel">
        <inertial>
            <origin rpy="0 0 0" xyz="2.8786848882411675e-07 0.008317531517497673 1.2677459453047657e-07" />
            <mass value="0.04179337834879549" />
            <inertia ixx="0.00016" ixy="0.0" ixz="0.0" iyy="0.000316" iyz="-0.0" izz="0.00016" />
        </inertial>
        <visual>
            <origin rpy="0 0 0" xyz="-0.514936 -0.05 -0.1016" />
            <geometry>
                <mesh filename="package://agribot_dummy_1_description/meshes/front_left_wheel_1.stl" scale="0.001 0.001 0.001" />
            </geometry>
            <material name="rubber_hard" />
        </visual>
        <collision>
            <origin rpy="0 0 0" xyz="-0.514936 -0.05 -0.1016" />
            <geometry>
                <mesh filename="package://agribot_dummy_1_description/meshes/front_left_wheel_1.stl" scale="0.001 0.001 0.001" />
            </geometry>
        </collision>
    </link>
    <link name="back_left_wheel">
        <inertial>
            <origin rpy="0 0 0" xyz="2.8786848866972636e-07 0.008317531517497881 1.2677459453047657e-07" />
            <mass value="0.04179337834879549" />
            <inertia ixx="0.00016" ixy="0.0" ixz="-0.0" iyy="0.000316" iyz="0.0" izz="0.00016" />
        </inertial>
        <visual>
            <origin rpy="0 0 0" xyz="0.015064 -0.05 -0.1016" />
            <geometry>
                <mesh filename="package://agribot_dummy_1_description/meshes/back_left_wheel_1.stl" scale="0.001 0.001 0.001" />
            </geometry>
            <material name="rubber_hard" />
        </visual>
        <collision>
            <origin rpy="0 0 0" xyz="0.015064 -0.05 -0.1016" />
            <geometry>
                <mesh filename="package://agribot_dummy_1_description/meshes/back_left_wheel_1.stl" scale="0.001 0.001 0.001" />
            </geometry>
        </collision>
    </link>
    <link name="back_right_wheel">
        <inertial>
            <origin rpy="0 0 0" xyz="2.878684886211541e-07 -0.008317531517497811 1.2677459453047657e-07" />
            <mass value="0.04179337834879549" />
            <inertia ixx="0.00016" ixy="0.0" ixz="0.0" iyy="0.000316" iyz="-0.0" izz="0.00016" />
        </inertial>
        <visual>
            <origin rpy="0 0 0" xyz="0.015064 0.41 -0.1016" />
            <geometry>
                <mesh filename="package://agribot_dummy_1_description/meshes/back_right_wheel_1.stl" scale="0.001 0.001 0.001" />
            </geometry>
            <material name="rubber_hard" />
        </visual>
        <collision>
            <origin rpy="0 0 0" xyz="0.015064 0.41 -0.1016" />
            <geometry>
                <mesh filename="package://agribot_dummy_1_description/meshes/back_right_wheel_1.stl" scale="0.001 0.001 0.001" />
            </geometry>
        </collision>
    </link>
    <link name="slider_link">
        <inertial>
            <origin rpy="0 0 0" xyz="0.049999744653985045 -2.220446049250313e-16 0.010064724681724257" />
            <mass value="0.4468199697005557" />
            <inertia ixx="0.000398" ixy="0.0" ixz="0.0" iyy="0.000608" iyz="0.0" izz="0.000954" />
        </inertial>
        <visual>
            <origin rpy="0 0 0" xyz="-0.340357 0.18 -0.334206" />
            <geometry>
                <mesh filename="package://agribot_dummy_1_description/meshes/slider_link_1.stl" scale="0.001 0.001 0.001" />
            </geometry>
            <material name="aluminum_satin" />
        </visual>
        <collision>
            <origin rpy="0 0 0" xyz="-0.340357 0.18 -0.334206" />
            <geometry>
                <mesh filename="package://agribot_dummy_1_description/meshes/slider_link_1.stl" scale="0.001 0.001 0.001" />
            </geometry>
        </collision>
    </link>
    <link name="arm_base">
        <inertial>
            <origin rpy="0 0 0" xyz="-2.5534600761600856e-07 4.163336342344337e-16 0.010307344162242882" />
            <mass value="0.9330886709339282" />
            <inertia ixx="0.001421" ixy="-0.0" ixz="-0.0" iyy="0.001421" iyz="0.0" izz="0.002578" />
        </inertial>
        <visual>
            <origin rpy="0 0 0" xyz="-0.390357 0.18 -0.354206" />
            <geometry>
                <mesh filename="package://agribot_dummy_1_description/meshes/arm_base_1.stl" scale="0.001 0.001 0.001" />
            </geometry>
            <material name="silver_default" />
        </visual>
        <collision>
            <origin rpy="0 0 0" xyz="-0.390357 0.18 -0.354206" />
            <geometry>
                <mesh filename="package://agribot_dummy_1_description/meshes/arm_base_1.stl" scale="0.001 0.001 0.001" />
            </geometry>
        </collision>
    </link>
    <link name="link_1">
        <inertial>
            <origin rpy="0 0 0" xyz="0.004456423186934566 0.003271946940343523 0.025593790212873335" />
            <mass value="1.6613467153005244" />
            <inertia ixx="0.002483" ixy="2.2e-05" ixz="-0.000454" iyy="0.002663" iyz="-0.000339" izz="0.002146" />
        </inertial>
        <visual>
            <origin rpy="0 0 0" xyz="-0.390357 0.18 -0.395206" />
            <geometry>
                <mesh filename="package://agribot_dummy_1_description/meshes/link_1_v3_1.stl" scale="0.001 0.001 0.001" />
            </geometry>
            <material name="opaque565656" />
        </visual>
        <collision>
            <origin rpy="0 0 0" xyz="-0.390357 0.18 -0.395206" />
            <geometry>
                <mesh filename="package://agribot_dummy_1_description/meshes/link_1_v3_1.stl" scale="0.001 0.001 0.001" />
            </geometry>
        </collision>
    </link>
    <link name="link_2">
        <inertial>
            <origin rpy="0 0 0" xyz="-0.005697039824627881 -0.0004995401177828596 0.0884670509482548" />
            <mass value="0.2532575834482899" />
            <inertia ixx="0.000761" ixy="0.0" ixz="5.6e-05" iyy="0.000795" iyz="0.0" izz="3.6e-05" />
        </inertial>
        <visual>
            <origin rpy="0 0 0" xyz="-0.431408 0.171289 -0.469946" />
            <geometry>
                <mesh filename="package://agribot_dummy_1_description/meshes/link_2__1__1.stl" scale="0.001 0.001 0.001" />
            </geometry>
            <material name="steel_satin" />
        </visual>
        <collision>
            <origin rpy="0 0 0" xyz="-0.431408 0.171289 -0.469946" />
            <geometry>
                <mesh filename="package://agribot_dummy_1_description/meshes/link_2__1__1.stl" scale="0.001 0.001 0.001" />
            </geometry>
        </collision>
    </link>
    <link name="link_3">
        <inertial>
            <origin rpy="0 0 0" xyz="0.04968904125333268 -0.01895305134049774 0.0013291327267154207" />
            <mass value="0.6682248227150333" />
            <inertia ixx="9.9e-05" ixy="9e-06" ixz="2.1e-05" iyy="0.002549" iyz="0.0" izz="0.00257" />
        </inertial>
        <visual>
            <origin rpy="0 0 0" xyz="-0.423276 0.174289 -0.646936" />
            <geometry>
                <mesh filename="package://agribot_dummy_1_description/meshes/link_3_v2_1.stl" scale="0.001 0.001 0.001" />
            </geometry>
            <material name="silver_default" />
        </visual>
        <collision>
            <origin rpy="0 0 0" xyz="-0.423276 0.174289 -0.646936" />
            <geometry>
                <mesh filename="package://agribot_dummy_1_description/meshes/link_3_v2_1.stl" scale="0.001 0.001 0.001" />
            </geometry>
        </collision>
    </link>
    <link name="eef_base">
        <inertial>
            <origin rpy="0 0 0" xyz="0.043185983208053336 -0.019105713731905394 0.004330577791318957" />
            <mass value="0.33153308863416714" />
            <inertia ixx="9.2e-05" ixy="0.0" ixz="-5e-06" iyy="9.1e-05" iyz="1e-06" izz="0.000121" />
        </inertial>
        <visual>
            <origin rpy="0 0 0" xyz="-0.5512 0.174589 -0.646936" />
            <geometry>
                <mesh filename="package://agribot_dummy_1_description/meshes/eef_base_v1_1.stl" scale="0.001 0.001 0.001" />
            </geometry>
            <material name="silver_default" />
        </visual>
        <collision>
            <origin rpy="0 0 0" xyz="-0.5512 0.174589 -0.646936" />
            <geometry>
                <mesh filename="package://agribot_dummy_1_description/meshes/eef_base_v1_1.stl" scale="0.001 0.001 0.001" />
            </geometry>
        </collision>
    </link>
    <link name="right_claw">
        <inertial>
            <origin rpy="0 0 0" xyz="0.01760998904896094 -0.06232708705438528 0.0008019626949357095" />
            <mass value="0.0273613159891005" />
            <inertia ixx="2.2e-05" ixy="9e-06" ixz="-0.0" iyy="4e-06" iyz="0.0" izz="2.7e-05" />
        </inertial>
        <visual>
            <origin rpy="0 0 0" xyz="-0.596135 0.225099 -0.637478" />
            <geometry>
                <mesh filename="package://agribot_dummy_1_description/meshes/right_claw_v3_1.stl" scale="0.001 0.001 0.001" />
            </geometry>
            <material name="silver_default" />
        </visual>
        <collision>
            <origin rpy="0 0 0" xyz="-0.596135 0.225099 -0.637478" />
            <geometry>
                <mesh filename="package://agribot_dummy_1_description/meshes/right_claw_v3_1.stl" scale="0.001 0.001 0.001" />
            </geometry>
        </collision>
    </link>
    <link name="left_claw">
        <inertial>
            <origin rpy="0 0 0" xyz="0.02296833455997338 0.060556652743396264 0.0008019626949468117" />
            <mass value="0.027361315989100136" />
            <inertia ixx="2.1e-05" ixy="-1e-05" ixz="-0.0" iyy="6e-06" iyz="-0.0" izz="2.7e-05" />
        </inertial>
        <visual>
            <origin rpy="0 0 0" xyz="-0.596135 0.162099 -0.637478" />
            <geometry>
                <mesh filename="package://agribot_dummy_1_description/meshes/left_claw_v3_1.stl" scale="0.001 0.001 0.001" />
            </geometry>
            <material name="silver_default" />
        </visual>
        <collision>
            <origin rpy="0 0 0" xyz="-0.596135 0.162099 -0.637478" />
            <geometry>
                <mesh filename="package://agribot_dummy_1_description/meshes/left_claw_v3_1.stl" scale="0.001 0.001 0.001" />
            </geometry>
        </collision>
    </link>
    <link name="cam_attachment">
        <inertial>
            <origin rpy="0 0 0" xyz="0.15746153034444033 -2.498001805406602e-16 0.07822756136912196" />
            <mass value="1.0263173373939967" />
            <inertia ixx="0.007817" ixy="0.0" ixz="-0.005237" iyy="0.012828" iyz="0.0" izz="0.005165" />
        </inertial>
        <visual>
            <origin rpy="0 0 0" xyz="-0.5 0.18 -0.349206" />
            <geometry>
                <mesh filename="package://agribot_dummy_1_description/meshes/cam_attachment_1.stl" scale="0.001 0.001 0.001" />
            </geometry>
            <material name="aluminum_satin" />
        </visual>
        <collision>
            <origin rpy="0 0 0" xyz="-0.5 0.18 -0.349206" />
            <geometry>
                <mesh filename="package://agribot_dummy_1_description/meshes/cam_attachment_1.stl" scale="0.001 0.001 0.001" />
            </geometry>
        </collision>
    </link>
    <link name="Kinect">
        <inertial>
            <origin rpy="0 0 0" xyz="-0.0022506378862189313 4.529465010386091e-05 0.04507191267797728" />
            <mass value="5.170544220159949" />
            <inertia ixx="0.024602" ixy="-7e-06" ixz="2.8e-05" iyy="0.00328" iyz="-3e-06" izz="0.024429" />
        </inertial>
        <visual>
            <origin rpy="0 0 0" xyz="-0.821066 0.18 -0.605272" />
            <geometry>
                <mesh filename="package://agribot_dummy_1_description/meshes/Kinect_1.stl" scale="0.001 0.001 0.001" />
            </geometry>
            <material name="opaque126126126" />
        </visual>
        <collision>
            <origin rpy="0 0 0" xyz="-0.821066 0.18 -0.605272" />
            <geometry>
                <mesh filename="package://agribot_dummy_1_description/meshes/Kinect_1.stl" scale="0.001 0.001 0.001" />
            </geometry>
        </collision>
    </link>
    <joint name="front_right" type="continuous">
        <origin rpy="0 0 0" xyz="0.515 -0.41 0.102206" />
        <parent link="base_link" />
        <child link="front_right_wheel" />
        <axis xyz="-0.0 1.0 0.0" />
    </joint>
    <joint name="front_left" type="continuous">
        <origin rpy="0 0 0" xyz="0.514936 0.05 0.1016" />
        <parent link="base_link" />
        <child link="front_left_wheel" />
        <axis xyz="0.0 1.0 0.0" />
    </joint>
    <joint name="back_left" type="continuous">
        <origin rpy="0 0 0" xyz="-0.015064 0.05 0.1016" />
        <parent link="base_link" />
        <child link="back_left_wheel" />
        <axis xyz="0.0 1.0 0.0" />
    </joint>
    <joint name="back_right" type="continuous">
        <origin rpy="0 0 0" xyz="-0.015064 -0.41 0.1016" />
        <parent link="base_link" />
        <child link="back_right_wheel" />
        <axis xyz="-0.0 1.0 0.0" />
    </joint>
    <joint name="Slider" type="prismatic">
        <origin rpy="0 0 0" xyz="0.340357 -0.18 0.334206" />
        <parent link="base_link" />
        <child link="slider_link" />
        <axis xyz="0.0 1.0 0.0" />
        <limit effort="100" lower="-0.10" upper="0.10" velocity="0.5" />
    </joint>
    <joint name="Rigid 15" type="fixed">
        <origin rpy="0 0 0" xyz="0.05 0.0 0.02" />
        <parent link="slider_link" />
        <child link="arm_base" />
    </joint>
    <joint name="arm_twist" type="continuous">
        <origin rpy="0 0 0" xyz="0.0 0.0 0.041" />
        <parent link="arm_base" />
        <child link="link_1" />
        <axis xyz="0.0 0.0 1.0" />
    </joint>
    <joint name="shoulder" type="continuous">
        <origin rpy="0 0 0" xyz="0.041051 0.008711 0.07474" />
        <parent link="link_1" />
        <child link="link_2" />
        <axis xyz="0.0 -1.0 -0.0" />
    </joint>
    <joint name="elbow" type="continuous">
        <origin rpy="0 0 0" xyz="-0.008132 -0.003 0.17699" />
        <parent link="link_2" />
        <child link="link_3" />
        <axis xyz="0.0 -1.0 -0.0" />
    </joint>
    <joint name="wrist" type="continuous">
        <origin rpy="0 0 0" xyz="0.127924 -0.0003 0.0" />
        <parent link="link_3" />
        <child link="eef_base" />
        <axis xyz="-0.0 1.0 0.0" />
    </joint>
    <joint name="right_finger" type="continuous">
        <origin rpy="0 0 0" xyz="0.044935 -0.05051 -0.009458" />
        <parent link="eef_base" />
        <child link="right_claw" />
        <axis xyz="-0.0 -0.0 1.0" />
    </joint>
    <joint name="left_finger" type="continuous">
        <origin rpy="0 0 0" xyz="0.044935 0.01249 -0.009458" />
        <parent link="eef_base" />
        <child link="left_claw" />
        <axis xyz="-0.0 -0.0 1.0" />
    </joint>
    <joint name="Rigid 22" type="fixed">
        <origin rpy="0 0 0" xyz="0.5 -0.18 0.349206" />
        <parent link="base_link" />
        <child link="cam_attachment" />
    </joint>
    <joint name="camera_twist" type="continuous">
        <origin rpy="0 0 0" xyz="0.321066 0.0 0.256066" />
        <parent link="cam_attachment" />
        <child link="Kinect" />
        <axis xyz="0.0 0.0 1.0" />
    </joint>
</robot>

