<?xml version="1.0" ?>
<!-- =================================================================================== -->
<!-- |    This document was autogenerated by xacro from /home/siddharth/ws_moveit/src/AgriBot/roarm_assembly_description/urdf/roarm_assembly.xacro | -->
<!-- |    EDITING THIS FILE BY HAND IS NOT RECOMMENDED                                 | -->
<!-- =================================================================================== -->
<robot name="roarm_assembly">
    <material name="silver_default">
        <color rgba="0.700 0.700 0.700 1.000" />
    </material>
    <material name="opaque565656">
        <color rgba="0.2196078431372549 0.2196078431372549 0.2196078431372549 1.0" />
    </material>
    <material name="steel_satin">
        <color rgba="0.6274509803921569 0.6274509803921569 0.6274509803921569 1.0" />
    </material>
    <transmission name="base_twist_tran">
        <type>transmission_interface/SimpleTransmission</type>
        <joint name="base_twist">
            <hardwareInterface>hardware_interface/PositionJointInterface</hardwareInterface>
        </joint>
        <actuator name="base_twist_actr">
            <hardwareInterface>hardware_interface/PositionJointInterface</hardwareInterface>
            <mechanicalReduction>1</mechanicalReduction>
        </actuator>
    </transmission>
    <transmission name="shoulder_tran">
        <type>transmission_interface/SimpleTransmission</type>
        <joint name="shoulder">
            <hardwareInterface>hardware_interface/PositionJointInterface</hardwareInterface>
        </joint>
        <actuator name="shoulder_actr">
            <hardwareInterface>hardware_interface/PositionJointInterface</hardwareInterface>
            <mechanicalReduction>1</mechanicalReduction>
        </actuator>
    </transmission>
    <transmission name="elbow_tran">
        <type>transmission_interface/SimpleTransmission</type>
        <joint name="elbow">
            <hardwareInterface>hardware_interface/PositionJointInterface</hardwareInterface>
        </joint>
        <actuator name="elbow_actr">
            <hardwareInterface>hardware_interface/PositionJointInterface</hardwareInterface>
            <mechanicalReduction>1</mechanicalReduction>
        </actuator>
    </transmission>
    <transmission name="wrist_tran">
        <type>transmission_interface/SimpleTransmission</type>
        <joint name="wrist">
            <hardwareInterface>hardware_interface/PositionJointInterface</hardwareInterface>
        </joint>
        <actuator name="wrist_actr">
            <hardwareInterface>hardware_interface/PositionJointInterface</hardwareInterface>
            <mechanicalReduction>1</mechanicalReduction>
        </actuator>
    </transmission>
    <transmission name="left_finger_tran">
        <type>transmission_interface/SimpleTransmission</type>
        <joint name="left_finger">
            <hardwareInterface>hardware_interface/PositionJointInterface</hardwareInterface>
        </joint>
        <actuator name="left_finger_actr">
            <hardwareInterface>hardware_interface/PositionJointInterface</hardwareInterface>
            <mechanicalReduction>1</mechanicalReduction>
        </actuator>
    </transmission>
    <transmission name="right_finger_tran">
        <type>transmission_interface/SimpleTransmission</type>
        <joint name="right_finger">
            <hardwareInterface>hardware_interface/PositionJointInterface</hardwareInterface>
        </joint>
        <actuator name="right_finger_actr">
            <hardwareInterface>hardware_interface/PositionJointInterface</hardwareInterface>
            <mechanicalReduction>1</mechanicalReduction>
        </actuator>
    </transmission>
<gazebo>
  <plugin name="control" filename="libgazebo_ros_control.so"/>
</gazebo>
    <gazebo reference="base_link">
        <material>Gazebo/Silver</material>
        <mu1>0.2</mu1>
        <mu2>0.2</mu2>
        <selfCollide>true</selfCollide>
        <gravity>true</gravity>
    </gazebo>
    <gazebo reference="link_1">
        <material>Gazebo/Silver</material>
        <mu1>0.2</mu1>
        <mu2>0.2</mu2>
        <selfCollide>true</selfCollide>
    </gazebo>
    <gazebo reference="link_2">
        <material>Gazebo/Silver</material>
        <mu1>0.2</mu1>
        <mu2>0.2</mu2>
        <selfCollide>true</selfCollide>
    </gazebo>
    <gazebo reference="link_3">
        <material>Gazebo/Silver</material>
        <mu1>0.2</mu1>
        <mu2>0.2</mu2>
        <selfCollide>true</selfCollide>
    </gazebo>
    <gazebo reference="eef_base">
        <material>Gazebo/Silver</material>
        <mu1>0.2</mu1>
        <mu2>0.2</mu2>
        <selfCollide>true</selfCollide>
    </gazebo>
    <gazebo reference="left_claw">
        <material>Gazebo/Silver</material>
        <mu1>0.2</mu1>
        <mu2>0.2</mu2>
        <selfCollide>true</selfCollide>
    </gazebo>
    <gazebo reference="right_claw">
        <material>Gazebo/Silver</material>
        <mu1>0.2</mu1>
        <mu2>0.2</mu2>
        <selfCollide>true</selfCollide>
    </gazebo>
    <link name="base_link">
        <inertial>
            <origin rpy="0 0 0" xyz="2.842170943040401e-16 1.6253665080512292e-15 0.010307344162242452" />
            <mass value="0.9330886709339293" />
            <inertia ixx="0.001421" ixy="0.0" ixz="0.0" iyy="0.001421" iyz="-0.0" izz="0.002578" />
        </inertial>
        <visual>
            <origin rpy="0 0 0" xyz="0 0 0" />
            <geometry>
                <mesh filename="package://roarm_assembly_description/meshes/base_link.stl" scale="0.001 0.001 0.001" />
            </geometry>
            <material name="silver_default" />
        </visual>
        <collision>
            <origin rpy="0 0 0" xyz="0 0 0" />
            <geometry>
                <mesh filename="package://roarm_assembly_description/meshes/base_link.stl" scale="0.001 0.001 0.001" />
            </geometry>
        </collision>
    </link>
    <link name="link_1">
        <inertial>
            <origin rpy="0 0 0" xyz="-0.003248824428456881 0.00456933378923944 0.025593798133347008" />
            <mass value="1.6261208283126793" />
            <inertia ixx="0.002624" ixy="-2.6e-05" ixz="0.000319" iyy="0.002426" iyz="-0.000455" izz="0.002118" />
        </inertial>
        <visual>
            <origin rpy="0 0 0" xyz="0.0 -0.0 -0.041" />
            <geometry>
                <mesh filename="package://roarm_assembly_description/meshes/link_1__1__1.stl" scale="0.001 0.001 0.001" />
            </geometry>
            <material name="opaque565656" />
        </visual>
        <collision>
            <origin rpy="0 0 0" xyz="0.0 -0.0 -0.041" />
            <geometry>
                <mesh filename="package://roarm_assembly_description/meshes/link_1__1__1.stl" scale="0.001 0.001 0.001" />
            </geometry>
        </collision>
    </link>
    <link name="link_2">
        <inertial>
            <origin rpy="0 0 0" xyz="0.0014995401177805212 0.0024349435050276605 0.08033532296460895" />
            <mass value="0.2532575834482899" />
            <inertia ixx="0.000795" ixy="0.0" ixz="-0.0" iyy="0.000761" iyz="5.6e-05" izz="3.6e-05" />
        </inertial>
        <visual>
            <origin rpy="0 0 0" xyz="0.008711 -0.041051 -0.11574" />
            <geometry>
                <mesh filename="package://roarm_assembly_description/meshes/link_2__1__1.stl" scale="0.001 0.001 0.001" />
            </geometry>
            <material name="steel_satin" />
        </visual>
        <collision>
            <origin rpy="0 0 0" xyz="0.008711 -0.041051 -0.11574" />
            <geometry>
                <mesh filename="package://roarm_assembly_description/meshes/link_2__1__1.stl" scale="0.001 0.001 0.001" />
            </geometry>
        </collision>
    </link>
    <link name="link_3">
        <inertial>
            <origin rpy="0 0 0" xyz="0.01895305134049728 0.04968902458298733 0.0013294047430696398" />
            <mass value="0.6682248227150333" />
            <inertia ixx="0.002549" ixy="-9e-06" ixz="-0.0" iyy="9.9e-05" iyz="2.1e-05" izz="0.00257" />
        </inertial>
        <visual>
            <origin rpy="0 0 0" xyz="0.004711 -0.041051 -0.284598" />
            <geometry>
                <mesh filename="package://roarm_assembly_description/meshes/link_3__1__1.stl" scale="0.001 0.001 0.001" />
            </geometry>
            <material name="silver_default" />
        </visual>
        <collision>
            <origin rpy="0 0 0" xyz="0.004711 -0.041051 -0.284598" />
            <geometry>
                <mesh filename="package://roarm_assembly_description/meshes/link_3__1__1.stl" scale="0.001 0.001 0.001" />
            </geometry>
        </collision>
    </link>
    <link name="eef_base">
        <inertial>
            <origin rpy="0 0 0" xyz="0.019105713731911726 0.04318596653770779 0.004330849807673176" />
            <mass value="0.33153308863416786" />
            <inertia ixx="9.1e-05" ixy="-0.0" ixz="-1e-06" iyy="9.2e-05" iyz="-5e-06" izz="0.000121" />
        </inertial>
        <visual>
            <origin rpy="0 0 0" xyz="0.004411 -0.168975 -0.284598" />
            <geometry>
                <mesh filename="package://roarm_assembly_description/meshes/eef_base_1.stl" scale="0.001 0.001 0.001" />
            </geometry>
            <material name="silver_default" />
        </visual>
        <collision>
            <origin rpy="0 0 0" xyz="0.004411 -0.168975 -0.284598" />
            <geometry>
                <mesh filename="package://roarm_assembly_description/meshes/eef_base_1.stl" scale="0.001 0.001 0.001" />
            </geometry>
        </collision>
    </link>
    <link name="left_claw">
        <inertial>
            <origin rpy="0 0 0" xyz="0.006511678868823683 0.0644377863644181 0.0008022347112953687" />
            <mass value="0.027361315989100073" />
            <inertia ixx="2.5e-05" ixy="-5e-06" ixz="-0.0" iyy="2e-06" iyz="-0.0" izz="2.7e-05" />
        </inertial>
        <visual>
            <origin rpy="0 0 0" xyz="0.016901 -0.21391 -0.27514" />
            <geometry>
                <mesh filename="package://roarm_assembly_description/meshes/left_claw_1.stl" scale="0.001 0.001 0.001" />
            </geometry>
            <material name="silver_default" />
        </visual>
        <collision>
            <origin rpy="0 0 0" xyz="0.016901 -0.21391 -0.27514" />
            <geometry>
                <mesh filename="package://roarm_assembly_description/meshes/left_claw_1.stl" scale="0.001 0.001 0.001" />
            </geometry>
        </collision>
    </link>
    <link name="right_claw">
        <inertial>
            <origin rpy="0 0 0" xyz="-0.0065193592272983075 0.06443898009782462 0.0008022347112930373" />
            <mass value="0.027361315989100486" />
            <inertia ixx="2.5e-05" ixy="5e-06" ixz="0.0" iyy="2e-06" iyz="-0.0" izz="2.7e-05" />
        </inertial>
        <visual>
            <origin rpy="0 0 0" xyz="-0.046099 -0.21391 -0.27514" />
            <geometry>
                <mesh filename="package://roarm_assembly_description/meshes/right_claw_1.stl" scale="0.001 0.001 0.001" />
            </geometry>
            <material name="silver_default" />
        </visual>
        <collision>
            <origin rpy="0 0 0" xyz="-0.046099 -0.21391 -0.27514" />
            <geometry>
                <mesh filename="package://roarm_assembly_description/meshes/right_claw_1.stl" scale="0.001 0.001 0.001" />
            </geometry>
        </collision>
    </link>
    <joint name="base_twist" type="continuous">
        <origin rpy="0 0 0" xyz="0.0 0.0 0.041" />
        <parent link="base_link" />
        <child link="link_1" />
        <axis xyz="0.0 0.0 1.0" />
    </joint>
    <joint name="shoulder" type="revolute">
        <origin rpy="0 0 0" xyz="-0.008711 0.041051 0.07474" />
        <parent link="link_1" />
        <child link="link_2" />
        <axis xyz="1.0 0.0 -0.0" />
        <limit effort="100" lower="-2.094395" upper="1.396263" velocity="100" />
    </joint>
    <joint name="elbow" type="revolute">
        <origin rpy="0 0 0" xyz="0.004 0.0 0.168858" />
        <parent link="link_2" />
        <child link="link_3" />
        <axis xyz="1.0 -0.0 -0.0" />
        <limit effort="100" lower="-2.617994" upper="2.617994" velocity="100" />
    </joint>
    <joint name="wrist" type="revolute">
        <origin rpy="0 0 0" xyz="0.0003 0.127924 0.0" />
        <parent link="link_3" />
        <child link="eef_base" />
        <axis xyz="-1.0 -0.0 0.0" />
        <limit effort="100" lower="-2.094395" upper="2.094395" velocity="100" />
    </joint>
    <joint name="left_finger" type="revolute">
        <origin rpy="0 0 0" xyz="-0.01249 0.044935 -0.009458" />
        <parent link="eef_base" />
        <child link="left_claw" />
        <axis xyz="0.0 -0.0 1.0" />
        <limit effort="100" lower="-0.261799" upper="1.308997" velocity="100" />
    </joint>
    <joint name="right_finger" type="revolute">
        <origin rpy="0 0 0" xyz="0.05051 0.044935 -0.009458" />
        <parent link="eef_base" />
        <child link="right_claw" />
        <axis xyz="0.0 -0.0 1.0" />
        <limit effort="100" lower="-1.308997" upper="0.261799" velocity="100" />
    </joint>
</robot>

