<?xml version="1.0" ?>
<robot name="agribot_dummy" xmlns:xacro="http://www.ros.org/wiki/xacro">

<xacro:include filename="$(find agribot_dummy_description)/urdf/materials.xacro" />
<xacro:include filename="$(find agribot_dummy_description)/urdf/agribot_dummy.trans" />
<xacro:include filename="$(find agribot_dummy_description)/urdf/agribot_dummy.gazebo" />
<link name="base_link">
  <inertial>
    <origin xyz="0.2514408376198744 -0.18000014406773893 0.22560750352264175" rpy="0 0 0"/>
    <mass value="12.394351278281407"/>
    <inertia ixx="0.331936" iyy="0.640231" izz="0.801659" ixy="-0.0" iyz="-0.0" ixz="-0.001939"/>
  </inertial>
  <visual>
    <origin xyz="0 0 0" rpy="0 0 0"/>
    <geometry>
      <mesh filename="package://agribot_dummy_description/meshes/base_link.stl" scale="0.001 0.001 0.001"/>
    </geometry>
    <material name="silver_default"/>
  </visual>
  <collision>
    <origin xyz="0 0 0" rpy="0 0 0"/>
    <geometry>
      <mesh filename="package://agribot_dummy_description/meshes/base_link.stl" scale="0.001 0.001 0.001"/>
    </geometry>
  </collision>
</link>

<link name="front_right_1">
  <inertial>
    <origin xyz="-1.1102230246251565e-16 -0.008317531517497756 3.774758283725532e-15" rpy="0 0 0"/>
    <mass value="0.04179337834879549"/>
    <inertia ixx="0.00016" iyy="0.000316" izz="0.00016" ixy="0.0" iyz="-0.0" ixz="-0.0"/>
  </inertial>
  <visual>
    <origin xyz="-0.515 0.41 -0.102206" rpy="0 0 0"/>
    <geometry>
      <mesh filename="package://agribot_dummy_description/meshes/front_right_1.stl" scale="0.001 0.001 0.001"/>
    </geometry>
    <material name="rubber_hard"/>
  </visual>
  <collision>
    <origin xyz="-0.515 0.41 -0.102206" rpy="0 0 0"/>
    <geometry>
      <mesh filename="package://agribot_dummy_description/meshes/front_right_1.stl" scale="0.001 0.001 0.001"/>
    </geometry>
  </collision>
</link>

<link name="front_left_1">
  <inertial>
    <origin xyz="2.8786848882411675e-07 0.008317531517497673 1.2677459453047657e-07" rpy="0 0 0"/>
    <mass value="0.04179337834879549"/>
    <inertia ixx="0.00016" iyy="0.000316" izz="0.00016" ixy="0.0" iyz="-0.0" ixz="0.0"/>
  </inertial>
  <visual>
    <origin xyz="-0.514936 -0.05 -0.1016" rpy="0 0 0"/>
    <geometry>
      <mesh filename="package://agribot_dummy_description/meshes/front_left_1.stl" scale="0.001 0.001 0.001"/>
    </geometry>
    <material name="rubber_hard"/>
  </visual>
  <collision>
    <origin xyz="-0.514936 -0.05 -0.1016" rpy="0 0 0"/>
    <geometry>
      <mesh filename="package://agribot_dummy_description/meshes/front_left_1.stl" scale="0.001 0.001 0.001"/>
    </geometry>
  </collision>
</link>

<link name="back_left_1">
  <inertial>
    <origin xyz="2.8786848866972636e-07 0.008317531517497881 1.2677459453047657e-07" rpy="0 0 0"/>
    <mass value="0.04179337834879549"/>
    <inertia ixx="0.00016" iyy="0.000316" izz="0.00016" ixy="0.0" iyz="0.0" ixz="-0.0"/>
  </inertial>
  <visual>
    <origin xyz="0.015064 -0.05 -0.1016" rpy="0 0 0"/>
    <geometry>
      <mesh filename="package://agribot_dummy_description/meshes/back_left_1.stl" scale="0.001 0.001 0.001"/>
    </geometry>
    <material name="rubber_hard"/>
  </visual>
  <collision>
    <origin xyz="0.015064 -0.05 -0.1016" rpy="0 0 0"/>
    <geometry>
      <mesh filename="package://agribot_dummy_description/meshes/back_left_1.stl" scale="0.001 0.001 0.001"/>
    </geometry>
  </collision>
</link>

<link name="back_right_1">
  <inertial>
    <origin xyz="2.878684886211541e-07 -0.008317531517497811 1.2677459453047657e-07" rpy="0 0 0"/>
    <mass value="0.04179337834879549"/>
    <inertia ixx="0.00016" iyy="0.000316" izz="0.00016" ixy="0.0" iyz="-0.0" ixz="0.0"/>
  </inertial>
  <visual>
    <origin xyz="0.015064 0.41 -0.1016" rpy="0 0 0"/>
    <geometry>
      <mesh filename="package://agribot_dummy_description/meshes/back_right_1.stl" scale="0.001 0.001 0.001"/>
    </geometry>
    <material name="rubber_hard"/>
  </visual>
  <collision>
    <origin xyz="0.015064 0.41 -0.1016" rpy="0 0 0"/>
    <geometry>
      <mesh filename="package://agribot_dummy_description/meshes/back_right_1.stl" scale="0.001 0.001 0.001"/>
    </geometry>
  </collision>
</link>

<link name="slider_link_1">
  <inertial>
    <origin xyz="0.04999974465398499 -2.220446049250313e-16 0.0025286735321224385" rpy="0 0 0"/>
    <mass value="0.5140876896849489"/>
    <inertia ixx="0.000448" iyy="0.001058" izz="0.001466" ixy="-0.0" iyz="0.0" ixz="0.0"/>
  </inertial>
  <visual>
    <origin xyz="-0.340357 0.18 -0.334206" rpy="0 0 0"/>
    <geometry>
      <mesh filename="package://agribot_dummy_description/meshes/slider_link_1.stl" scale="0.001 0.001 0.001"/>
    </geometry>
    <material name="steel_satin"/>
  </visual>
  <collision>
    <origin xyz="-0.340357 0.18 -0.334206" rpy="0 0 0"/>
    <geometry>
      <mesh filename="package://agribot_dummy_description/meshes/slider_link_1.stl" scale="0.001 0.001 0.001"/>
    </geometry>
  </collision>
</link>

<link name="arm_base_1">
  <inertial>
    <origin xyz="-2.553460147214359e-07 -4.718447854656915e-16 0.010307344162242604" rpy="0 0 0"/>
    <mass value="0.9330886709339282"/>
    <inertia ixx="0.001421" iyy="0.001421" izz="0.002578" ixy="0.0" iyz="-0.0" ixz="0.0"/>
  </inertial>
  <visual>
    <origin xyz="-0.390357 0.18 -0.344206" rpy="0 0 0"/>
    <geometry>
      <mesh filename="package://agribot_dummy_description/meshes/arm_base_1.stl" scale="0.001 0.001 0.001"/>
    </geometry>
    <material name="silver_default"/>
  </visual>
  <collision>
    <origin xyz="-0.390357 0.18 -0.344206" rpy="0 0 0"/>
    <geometry>
      <mesh filename="package://agribot_dummy_description/meshes/arm_base_1.stl" scale="0.001 0.001 0.001"/>
    </geometry>
  </collision>
</link>

<link name="link_1_v3_1">
  <inertial>
    <origin xyz="0.004456423186927294 0.003271946940342607 0.02559379021287267" rpy="0 0 0"/>
    <mass value="1.6613467153005244"/>
    <inertia ixx="0.002483" iyy="0.002663" izz="0.002146" ixy="2.2e-05" iyz="-0.000339" ixz="-0.000454"/>
  </inertial>
  <visual>
    <origin xyz="-0.390357 0.18 -0.385206" rpy="0 0 0"/>
    <geometry>
      <mesh filename="package://agribot_dummy_description/meshes/link_1_v3_1.stl" scale="0.001 0.001 0.001"/>
    </geometry>
    <material name="opaque565656"/>
  </visual>
  <collision>
    <origin xyz="-0.390357 0.18 -0.385206" rpy="0 0 0"/>
    <geometry>
      <mesh filename="package://agribot_dummy_description/meshes/link_1_v3_1.stl" scale="0.001 0.001 0.001"/>
    </geometry>
  </collision>
</link>

<link name="link_2__1__1">
  <inertial>
    <origin xyz="0.002434688159009879 -0.0004995401177831926 0.08033532296460916" rpy="0 0 0"/>
    <mass value="0.2532575834482899"/>
    <inertia ixx="0.000761" iyy="0.000795" izz="3.6e-05" ixy="-0.0" iyz="0.0" ixz="5.6e-05"/>
  </inertial>
  <visual>
    <origin xyz="-0.431408 0.171289 -0.459946" rpy="0 0 0"/>
    <geometry>
      <mesh filename="package://agribot_dummy_description/meshes/link_2__1__1.stl" scale="0.001 0.001 0.001"/>
    </geometry>
    <material name="steel_satin"/>
  </visual>
  <collision>
    <origin xyz="-0.431408 0.171289 -0.459946" rpy="0 0 0"/>
    <geometry>
      <mesh filename="package://agribot_dummy_description/meshes/link_2__1__1.stl" scale="0.001 0.001 0.001"/>
    </geometry>
  </collision>
</link>

<link name="link_3_v2_1">
  <inertial>
    <origin xyz="0.049688769236970576 -0.01895305134049785 0.0013294047430694178" rpy="0 0 0"/>
    <mass value="0.6682248227150333"/>
    <inertia ixx="9.9e-05" iyy="0.002549" izz="0.00257" ixy="9e-06" iyz="0.0" ixz="2.1e-05"/>
  </inertial>
  <visual>
    <origin xyz="-0.431408 0.174289 -0.628804" rpy="0 0 0"/>
    <geometry>
      <mesh filename="package://agribot_dummy_description/meshes/link_3_v2_1.stl" scale="0.001 0.001 0.001"/>
    </geometry>
    <material name="silver_default"/>
  </visual>
  <collision>
    <origin xyz="-0.431408 0.174289 -0.628804" rpy="0 0 0"/>
    <geometry>
      <mesh filename="package://agribot_dummy_description/meshes/link_3_v2_1.stl" scale="0.001 0.001 0.001"/>
    </geometry>
  </collision>
</link>

<link name="eef_base_v1_1">
  <inertial>
    <origin xyz="0.043186711191691485 -0.019105713731905283 0.004330849807672732" rpy="0 0 0"/>
    <mass value="0.33153308863416714"/>
    <inertia ixx="9.2e-05" iyy="9.1e-05" izz="0.000121" ixy="0.0" iyz="1e-06" ixz="-5e-06"/>
  </inertial>
  <visual>
    <origin xyz="-0.559331 0.174589 -0.628804" rpy="0 0 0"/>
    <geometry>
      <mesh filename="package://agribot_dummy_description/meshes/eef_base_v1_1.stl" scale="0.001 0.001 0.001"/>
    </geometry>
    <material name="silver_default"/>
  </visual>
  <collision>
    <origin xyz="-0.559331 0.174589 -0.628804" rpy="0 0 0"/>
    <geometry>
      <mesh filename="package://agribot_dummy_description/meshes/eef_base_v1_1.stl" scale="0.001 0.001 0.001"/>
    </geometry>
  </collision>
</link>

<link name="right_claw_v3_1">
  <inertial>
    <origin xyz="0.017609717032599392 -0.06232708705438528 0.0008022347112897066" rpy="0 0 0"/>
    <mass value="0.0273613159891005"/>
    <inertia ixx="2.2e-05" iyy="4e-06" izz="2.7e-05" ixy="9e-06" iyz="0.0" ixz="-0.0"/>
  </inertial>
  <visual>
    <origin xyz="-0.604267 0.225099 -0.619346" rpy="0 0 0"/>
    <geometry>
      <mesh filename="package://agribot_dummy_description/meshes/right_claw_v3_1.stl" scale="0.001 0.001 0.001"/>
    </geometry>
    <material name="silver_default"/>
  </visual>
  <collision>
    <origin xyz="-0.604267 0.225099 -0.619346" rpy="0 0 0"/>
    <geometry>
      <mesh filename="package://agribot_dummy_description/meshes/right_claw_v3_1.stl" scale="0.001 0.001 0.001"/>
    </geometry>
  </collision>
</link>

<link name="left_claw_v3_1">
  <inertial>
    <origin xyz="0.017602842595918156 0.062327997414336436 0.0013022347113003097" rpy="0 0 0"/>
    <mass value="0.027361315989100177"/>
    <inertia ixx="2.2e-05" iyy="4e-06" izz="2.7e-05" ixy="-9e-06" iyz="-0.0" ixz="-0.0"/>
  </inertial>
  <visual>
    <origin xyz="-0.604267 0.162099 -0.619346" rpy="0 0 0"/>
    <geometry>
      <mesh filename="package://agribot_dummy_description/meshes/left_claw_v3_1.stl" scale="0.001 0.001 0.001"/>
    </geometry>
    <material name="silver_default"/>
  </visual>
  <collision>
    <origin xyz="-0.604267 0.162099 -0.619346" rpy="0 0 0"/>
    <geometry>
      <mesh filename="package://agribot_dummy_description/meshes/left_claw_v3_1.stl" scale="0.001 0.001 0.001"/>
    </geometry>
  </collision>
</link>

<joint name="front_right" type="continuous">
  <origin xyz="0.515 -0.41 0.102206" rpy="0 0 0"/>
  <parent link="base_link"/>
  <child link="front_right_1"/>
  <axis xyz="-0.0 -1.0 0.0"/>
</joint>

<joint name="front_left" type="continuous">
  <origin xyz="0.514936 0.05 0.1016" rpy="0 0 0"/>
  <parent link="base_link"/>
  <child link="front_left_1"/>
  <axis xyz="0.0 1.0 0.0"/>
</joint>

<joint name="back_left" type="continuous">
  <origin xyz="-0.015064 0.05 0.1016" rpy="0 0 0"/>
  <parent link="base_link"/>
  <child link="back_left_1"/>
  <axis xyz="0.0 1.0 0.0"/>
</joint>

<joint name="back_right" type="continuous">
  <origin xyz="-0.015064 -0.41 0.1016" rpy="0 0 0"/>
  <parent link="base_link"/>
  <child link="back_right_1"/>
  <axis xyz="-0.0 -1.0 0.0"/>
</joint>

<joint name="arm_slider" type="prismatic">
  <origin xyz="0.340357 -0.18 0.334206" rpy="0 0 0"/>
  <parent link="base_link"/>
  <child link="slider_link_1"/>
  <axis xyz="0.0 1.0 0.0"/>
  <limit upper="0.0" lower="0.0" effort="100" velocity="100"/>
</joint>

<joint name="Rigid 6" type="fixed">
  <origin xyz="0.05 0.0 0.01" rpy="0 0 0"/>
  <parent link="slider_link_1"/>
  <child link="arm_base_1"/>
</joint>

<joint name="arm_twist" type="continuous">
  <origin xyz="0.0 0.0 0.041" rpy="0 0 0"/>
  <parent link="arm_base_1"/>
  <child link="link_1_v3_1"/>
  <axis xyz="0.0 0.0 1.0"/>
</joint>

<joint name="shoulder" type="continuous">
  <origin xyz="0.041051 0.008711 0.07474" rpy="0 0 0"/>
  <parent link="link_1_v3_1"/>
  <child link="link_2__1__1"/>
  <axis xyz="0.0 -1.0 -0.0"/>
</joint>

<joint name="elbow" type="continuous">
  <origin xyz="0.0 -0.003 0.168858" rpy="0 0 0"/>
  <parent link="link_2__1__1"/>
  <child link="link_3_v2_1"/>
  <axis xyz="0.0 -1.0 -0.0"/>
</joint>

<joint name="wrist" type="continuous">
  <origin xyz="0.127923 -0.0003 0.0" rpy="0 0 0"/>
  <parent link="link_3_v2_1"/>
  <child link="eef_base_v1_1"/>
  <axis xyz="-0.0 1.0 0.0"/>
</joint>

<joint name="right_finger" type="continuous">
  <origin xyz="0.044936 -0.05051 -0.009458" rpy="0 0 0"/>
  <parent link="eef_base_v1_1"/>
  <child link="right_claw_v3_1"/>
  <axis xyz="-0.0 -0.0 1.0"/>
</joint>

<joint name="left_finger" type="continuous">
  <origin xyz="0.044936 0.01249 -0.009458" rpy="0 0 0"/>
  <parent link="eef_base_v1_1"/>
  <child link="left_claw_v3_1"/>
  <axis xyz="-0.0 -0.0 1.0"/>
</joint>

</robot>
