<?xml version="1.0" ?>
<robot name="agribot_dummy_1" xmlns:xacro="http://www.ros.org/wiki/xacro">

<xacro:include filename="$(find agribot_dummy_1_description)/urdf/materials.xacro" />
<xacro:include filename="$(find agribot_dummy_1_description)/urdf/agribot_dummy_1.trans" />
<xacro:include filename="$(find agribot_dummy_1_description)/urdf/agribot_dummy_1.gazebo" />
<link name="base_link">
  <inertial>
    <origin xyz="0.2514408376198744 -0.18000014406773893 0.22560750352264175" rpy="0 0 0"/>
    <mass value="12.394351278281407"/>
    <inertia ixx="0.331936" iyy="0.640231" izz="0.801659" ixy="-0.0" iyz="-0.0" ixz="-0.001939"/>
  </inertial>
  <visual>
    <origin xyz="0 0 0" rpy="0 0 0"/>
    <geometry>
      <mesh filename="package://agribot_dummy_1_description/meshes/base_link.stl" scale="0.001 0.001 0.001"/>
    </geometry>
    <material name="silver_default"/>
  </visual>
  <collision>
    <origin xyz="0 0 0" rpy="0 0 0"/>
    <geometry>
      <mesh filename="package://agribot_dummy_1_description/meshes/base_link.stl" scale="0.001 0.001 0.001"/>
    </geometry>
  </collision>
</link>

<link name="front_right_wheel_1">
  <inertial>
    <origin xyz="-1.1102230246251565e-16 -0.008317531517497756 3.774758283725532e-15" rpy="0 0 0"/>
    <mass value="0.04179337834879549"/>
    <inertia ixx="0.00016" iyy="0.000316" izz="0.00016" ixy="0.0" iyz="-0.0" ixz="-0.0"/>
  </inertial>
  <visual>
    <origin xyz="-0.515 0.41 -0.102206" rpy="0 0 0"/>
    <geometry>
      <mesh filename="package://agribot_dummy_1_description/meshes/front_right_wheel_1.stl" scale="0.001 0.001 0.001"/>
    </geometry>
    <material name="rubber_hard"/>
  </visual>
  <collision>
    <origin xyz="-0.515 0.41 -0.102206" rpy="0 0 0"/>
    <geometry>
      <mesh filename="package://agribot_dummy_1_description/meshes/front_right_wheel_1.stl" scale="0.001 0.001 0.001"/>
    </geometry>
  </collision>
</link>

<link name="front_left_wheel_1">
  <inertial>
    <origin xyz="2.8786848882411675e-07 0.008317531517497673 1.2677459453047657e-07" rpy="0 0 0"/>
    <mass value="0.04179337834879549"/>
    <inertia ixx="0.00016" iyy="0.000316" izz="0.00016" ixy="0.0" iyz="-0.0" ixz="0.0"/>
  </inertial>
  <visual>
    <origin xyz="-0.514936 -0.05 -0.1016" rpy="0 0 0"/>
    <geometry>
      <mesh filename="package://agribot_dummy_1_description/meshes/front_left_wheel_1.stl" scale="0.001 0.001 0.001"/>
    </geometry>
    <material name="rubber_hard"/>
  </visual>
  <collision>
    <origin xyz="-0.514936 -0.05 -0.1016" rpy="0 0 0"/>
    <geometry>
      <mesh filename="package://agribot_dummy_1_description/meshes/front_left_wheel_1.stl" scale="0.001 0.001 0.001"/>
    </geometry>
  </collision>
</link>

<link name="back_left_wheel_1">
  <inertial>
    <origin xyz="2.8786848866972636e-07 0.008317531517497881 1.2677459453047657e-07" rpy="0 0 0"/>
    <mass value="0.04179337834879549"/>
    <inertia ixx="0.00016" iyy="0.000316" izz="0.00016" ixy="0.0" iyz="0.0" ixz="-0.0"/>
  </inertial>
  <visual>
    <origin xyz="0.015064 -0.05 -0.1016" rpy="0 0 0"/>
    <geometry>
      <mesh filename="package://agribot_dummy_1_description/meshes/back_left_wheel_1.stl" scale="0.001 0.001 0.001"/>
    </geometry>
    <material name="rubber_hard"/>
  </visual>
  <collision>
    <origin xyz="0.015064 -0.05 -0.1016" rpy="0 0 0"/>
    <geometry>
      <mesh filename="package://agribot_dummy_1_description/meshes/back_left_wheel_1.stl" scale="0.001 0.001 0.001"/>
    </geometry>
  </collision>
</link>

<link name="back_right_wheel_1">
  <inertial>
    <origin xyz="2.878684886211541e-07 -0.008317531517497811 1.2677459453047657e-07" rpy="0 0 0"/>
    <mass value="0.04179337834879549"/>
    <inertia ixx="0.00016" iyy="0.000316" izz="0.00016" ixy="0.0" iyz="-0.0" ixz="0.0"/>
  </inertial>
  <visual>
    <origin xyz="0.015064 0.41 -0.1016" rpy="0 0 0"/>
    <geometry>
      <mesh filename="package://agribot_dummy_1_description/meshes/back_right_wheel_1.stl" scale="0.001 0.001 0.001"/>
    </geometry>
    <material name="rubber_hard"/>
  </visual>
  <collision>
    <origin xyz="0.015064 0.41 -0.1016" rpy="0 0 0"/>
    <geometry>
      <mesh filename="package://agribot_dummy_1_description/meshes/back_right_wheel_1.stl" scale="0.001 0.001 0.001"/>
    </geometry>
  </collision>
</link>

<link name="slider_link_1">
  <inertial>
    <origin xyz="0.049999744653985045 -2.220446049250313e-16 0.010064724681724257" rpy="0 0 0"/>
    <mass value="0.4468199697005557"/>
    <inertia ixx="0.000398" iyy="0.000608" izz="0.000954" ixy="0.0" iyz="0.0" ixz="0.0"/>
  </inertial>
  <visual>
    <origin xyz="-0.340357 0.18 -0.334206" rpy="0 0 0"/>
    <geometry>
      <mesh filename="package://agribot_dummy_1_description/meshes/slider_link_1.stl" scale="0.001 0.001 0.001"/>
    </geometry>
    <material name="aluminum_satin"/>
  </visual>
  <collision>
    <origin xyz="-0.340357 0.18 -0.334206" rpy="0 0 0"/>
    <geometry>
      <mesh filename="package://agribot_dummy_1_description/meshes/slider_link_1.stl" scale="0.001 0.001 0.001"/>
    </geometry>
  </collision>
</link>

<link name="arm_base_1">
  <inertial>
    <origin xyz="-2.5534600761600856e-07 4.163336342344337e-16 0.010307344162242882" rpy="0 0 0"/>
    <mass value="0.9330886709339282"/>
    <inertia ixx="0.001421" iyy="0.001421" izz="0.002578" ixy="-0.0" iyz="0.0" ixz="-0.0"/>
  </inertial>
  <visual>
    <origin xyz="-0.390357 0.18 -0.354206" rpy="0 0 0"/>
    <geometry>
      <mesh filename="package://agribot_dummy_1_description/meshes/arm_base_1.stl" scale="0.001 0.001 0.001"/>
    </geometry>
    <material name="silver_default"/>
  </visual>
  <collision>
    <origin xyz="-0.390357 0.18 -0.354206" rpy="0 0 0"/>
    <geometry>
      <mesh filename="package://agribot_dummy_1_description/meshes/arm_base_1.stl" scale="0.001 0.001 0.001"/>
    </geometry>
  </collision>
</link>

<link name="link_1_v3_1">
  <inertial>
    <origin xyz="0.004456423186934566 0.003271946940343523 0.025593790212873335" rpy="0 0 0"/>
    <mass value="1.6613467153005244"/>
    <inertia ixx="0.002483" iyy="0.002663" izz="0.002146" ixy="2.2e-05" iyz="-0.000339" ixz="-0.000454"/>
  </inertial>
  <visual>
    <origin xyz="-0.390357 0.18 -0.395206" rpy="0 0 0"/>
    <geometry>
      <mesh filename="package://agribot_dummy_1_description/meshes/link_1_v3_1.stl" scale="0.001 0.001 0.001"/>
    </geometry>
    <material name="opaque565656"/>
  </visual>
  <collision>
    <origin xyz="-0.390357 0.18 -0.395206" rpy="0 0 0"/>
    <geometry>
      <mesh filename="package://agribot_dummy_1_description/meshes/link_1_v3_1.stl" scale="0.001 0.001 0.001"/>
    </geometry>
  </collision>
</link>

<link name="link_2__1__1">
  <inertial>
    <origin xyz="-0.005697039824627881 -0.0004995401177828596 0.0884670509482548" rpy="0 0 0"/>
    <mass value="0.2532575834482899"/>
    <inertia ixx="0.000761" iyy="0.000795" izz="3.6e-05" ixy="0.0" iyz="0.0" ixz="5.6e-05"/>
  </inertial>
  <visual>
    <origin xyz="-0.431408 0.171289 -0.469946" rpy="0 0 0"/>
    <geometry>
      <mesh filename="package://agribot_dummy_1_description/meshes/link_2__1__1.stl" scale="0.001 0.001 0.001"/>
    </geometry>
    <material name="steel_satin"/>
  </visual>
  <collision>
    <origin xyz="-0.431408 0.171289 -0.469946" rpy="0 0 0"/>
    <geometry>
      <mesh filename="package://agribot_dummy_1_description/meshes/link_2__1__1.stl" scale="0.001 0.001 0.001"/>
    </geometry>
  </collision>
</link>

<link name="link_3_v2_1">
  <inertial>
    <origin xyz="0.04968904125333268 -0.01895305134049774 0.0013291327267154207" rpy="0 0 0"/>
    <mass value="0.6682248227150333"/>
    <inertia ixx="9.9e-05" iyy="0.002549" izz="0.00257" ixy="9e-06" iyz="0.0" ixz="2.1e-05"/>
  </inertial>
  <visual>
    <origin xyz="-0.423276 0.174289 -0.646936" rpy="0 0 0"/>
    <geometry>
      <mesh filename="package://agribot_dummy_1_description/meshes/link_3_v2_1.stl" scale="0.001 0.001 0.001"/>
    </geometry>
    <material name="silver_default"/>
  </visual>
  <collision>
    <origin xyz="-0.423276 0.174289 -0.646936" rpy="0 0 0"/>
    <geometry>
      <mesh filename="package://agribot_dummy_1_description/meshes/link_3_v2_1.stl" scale="0.001 0.001 0.001"/>
    </geometry>
  </collision>
</link>

<link name="eef_base_v1_1">
  <inertial>
    <origin xyz="0.043185983208053336 -0.019105713731905394 0.004330577791318957" rpy="0 0 0"/>
    <mass value="0.33153308863416714"/>
    <inertia ixx="9.2e-05" iyy="9.1e-05" izz="0.000121" ixy="0.0" iyz="1e-06" ixz="-5e-06"/>
  </inertial>
  <visual>
    <origin xyz="-0.5512 0.174589 -0.646936" rpy="0 0 0"/>
    <geometry>
      <mesh filename="package://agribot_dummy_1_description/meshes/eef_base_v1_1.stl" scale="0.001 0.001 0.001"/>
    </geometry>
    <material name="silver_default"/>
  </visual>
  <collision>
    <origin xyz="-0.5512 0.174589 -0.646936" rpy="0 0 0"/>
    <geometry>
      <mesh filename="package://agribot_dummy_1_description/meshes/eef_base_v1_1.stl" scale="0.001 0.001 0.001"/>
    </geometry>
  </collision>
</link>

<link name="right_claw_v3_1">
  <inertial>
    <origin xyz="0.01760998904896094 -0.06232708705438528 0.0008019626949357095" rpy="0 0 0"/>
    <mass value="0.0273613159891005"/>
    <inertia ixx="2.2e-05" iyy="4e-06" izz="2.7e-05" ixy="9e-06" iyz="0.0" ixz="-0.0"/>
  </inertial>
  <visual>
    <origin xyz="-0.596135 0.225099 -0.637478" rpy="0 0 0"/>
    <geometry>
      <mesh filename="package://agribot_dummy_1_description/meshes/right_claw_v3_1.stl" scale="0.001 0.001 0.001"/>
    </geometry>
    <material name="silver_default"/>
  </visual>
  <collision>
    <origin xyz="-0.596135 0.225099 -0.637478" rpy="0 0 0"/>
    <geometry>
      <mesh filename="package://agribot_dummy_1_description/meshes/right_claw_v3_1.stl" scale="0.001 0.001 0.001"/>
    </geometry>
  </collision>
</link>

<link name="left_claw_v3_1">
  <inertial>
    <origin xyz="0.02296833455997338 0.060556652743396264 0.0008019626949468117" rpy="0 0 0"/>
    <mass value="0.027361315989100136"/>
    <inertia ixx="2.1e-05" iyy="6e-06" izz="2.7e-05" ixy="-1e-05" iyz="-0.0" ixz="-0.0"/>
  </inertial>
  <visual>
    <origin xyz="-0.596135 0.162099 -0.637478" rpy="0 0 0"/>
    <geometry>
      <mesh filename="package://agribot_dummy_1_description/meshes/left_claw_v3_1.stl" scale="0.001 0.001 0.001"/>
    </geometry>
    <material name="silver_default"/>
  </visual>
  <collision>
    <origin xyz="-0.596135 0.162099 -0.637478" rpy="0 0 0"/>
    <geometry>
      <mesh filename="package://agribot_dummy_1_description/meshes/left_claw_v3_1.stl" scale="0.001 0.001 0.001"/>
    </geometry>
  </collision>
</link>

<link name="cam_attachment_1">
  <inertial>
    <origin xyz="0.15746153034444033 -2.498001805406602e-16 0.07822756136912196" rpy="0 0 0"/>
    <mass value="1.0263173373939967"/>
    <inertia ixx="0.007817" iyy="0.012828" izz="0.005165" ixy="0.0" iyz="0.0" ixz="-0.005237"/>
  </inertial>
  <visual>
    <origin xyz="-0.5 0.18 -0.349206" rpy="0 0 0"/>
    <geometry>
      <mesh filename="package://agribot_dummy_1_description/meshes/cam_attachment_1.stl" scale="0.001 0.001 0.001"/>
    </geometry>
    <material name="aluminum_satin"/>
  </visual>
  <collision>
    <origin xyz="-0.5 0.18 -0.349206" rpy="0 0 0"/>
    <geometry>
      <mesh filename="package://agribot_dummy_1_description/meshes/cam_attachment_1.stl" scale="0.001 0.001 0.001"/>
    </geometry>
  </collision>
</link>

<link name="Kinect_1">
  <inertial>
    <origin xyz="-0.0022506378862189313 4.529465010386091e-05 0.04507191267797728" rpy="0 0 0"/>
    <mass value="5.170544220159949"/>
    <inertia ixx="0.024602" iyy="0.00328" izz="0.024429" ixy="-7e-06" iyz="-3e-06" ixz="2.8e-05"/>
  </inertial>
  <visual>
    <origin xyz="-0.721066 0.18 -0.605272" rpy="0 0 0"/>
    <geometry>
      <mesh filename="package://agribot_dummy_1_description/meshes/Kinect_1.stl" scale="0.001 0.001 0.001"/>
    </geometry>
    <material name="opaque126126126"/>
  </visual>
  <collision>
    <origin xyz="-0.721066 0.18 -0.605272" rpy="0 0 0"/>
    <geometry>
      <mesh filename="package://agribot_dummy_1_description/meshes/Kinect_1.stl" scale="0.001 0.001 0.001"/>
    </geometry>
  </collision>
</link>

<joint name="front_right" type="continuous">
  <origin xyz="0.515 -0.41 0.102206" rpy="0 0 0"/>
  <parent link="base_link"/>
  <child link="front_right_wheel_1"/>
  <axis xyz="-0.0 -1.0 0.0"/>
</joint>

<joint name="front_left" type="continuous">
  <origin xyz="0.514936 0.05 0.1016" rpy="0 0 0"/>
  <parent link="base_link"/>
  <child link="front_left_wheel_1"/>
  <axis xyz="0.0 1.0 0.0"/>
</joint>

<joint name="back_left" type="continuous">
  <origin xyz="-0.015064 0.05 0.1016" rpy="0 0 0"/>
  <parent link="base_link"/>
  <child link="back_left_wheel_1"/>
  <axis xyz="0.0 1.0 0.0"/>
</joint>

<joint name="back_right" type="continuous">
  <origin xyz="-0.015064 -0.41 0.1016" rpy="0 0 0"/>
  <parent link="base_link"/>
  <child link="back_right_wheel_1"/>
  <axis xyz="-0.0 -1.0 0.0"/>
</joint>

<joint name="Slider 14" type="prismatic">
  <origin xyz="0.340357 -0.18 0.334206" rpy="0 0 0"/>
  <parent link="base_link"/>
  <child link="slider_link_1"/>
  <axis xyz="0.0 1.0 0.0"/>
  <limit upper="0.0" lower="0.0" effort="100" velocity="100"/>
</joint>

<joint name="Rigid 15" type="fixed">
  <origin xyz="0.05 0.0 0.02" rpy="0 0 0"/>
  <parent link="slider_link_1"/>
  <child link="arm_base_1"/>
</joint>

<joint name="arm_twist" type="continuous">
  <origin xyz="0.0 0.0 0.041" rpy="0 0 0"/>
  <parent link="arm_base_1"/>
  <child link="link_1_v3_1"/>
  <axis xyz="0.0 0.0 1.0"/>
</joint>

<joint name="shoulder" type="continuous">
  <origin xyz="0.041051 0.008711 0.07474" rpy="0 0 0"/>
  <parent link="link_1_v3_1"/>
  <child link="link_2__1__1"/>
  <axis xyz="0.0 -1.0 -0.0"/>
</joint>

<joint name="elbow" type="continuous">
  <origin xyz="-0.008132 -0.003 0.17699" rpy="0 0 0"/>
  <parent link="link_2__1__1"/>
  <child link="link_3_v2_1"/>
  <axis xyz="0.0 -1.0 -0.0"/>
</joint>

<joint name="wrist" type="continuous">
  <origin xyz="0.127924 -0.0003 0.0" rpy="0 0 0"/>
  <parent link="link_3_v2_1"/>
  <child link="eef_base_v1_1"/>
  <axis xyz="-0.0 1.0 0.0"/>
</joint>

<joint name="right_finger" type="continuous">
  <origin xyz="0.044935 -0.05051 -0.009458" rpy="0 0 0"/>
  <parent link="eef_base_v1_1"/>
  <child link="right_claw_v3_1"/>
  <axis xyz="-0.0 -0.0 1.0"/>
</joint>

<joint name="left_finger" type="continuous">
  <origin xyz="0.044935 0.01249 -0.009458" rpy="0 0 0"/>
  <parent link="eef_base_v1_1"/>
  <child link="left_claw_v3_1"/>
  <axis xyz="-0.0 -0.0 1.0"/>
</joint>

<joint name="Rigid 22" type="fixed">
  <origin xyz="0.5 -0.18 0.349206" rpy="0 0 0"/>
  <parent link="base_link"/>
  <child link="cam_attachment_1"/>
</joint>

<joint name="camera_twist" type="continuous">
  <origin xyz="0.221066 0.0 0.256066" rpy="0 0 0"/>
  <parent link="cam_attachment_1"/>
  <child link="Kinect_1"/>
  <axis xyz="0.0 0.0 1.0"/>
</joint>

</robot>
